<?xml version="1.0" ?>
<!-- =================================================================================== -->
<!-- |    This document was autogenerated by xacro from birdy_v1.xacro             | -->
<!-- |    EDITING THIS FILE BY HAND IS NOT RECOMMENDED                                 | -->
<!-- =================================================================================== -->
<robot name="birdy_v1">
<!--<link name="world">
</link>-->
<!--<joint name="joint_fixed_world" type="floating">
  <origin rpy="0 0 0" xyz="0 0 0.65"/>
  <parent link="world"/>
  <child link="link_trunk"/>
</joint>-->
  <link name="link_trunk">
    <inertial>
      <origin rpy="0 0 0" xyz="0.1 0 0.0272"/>
      <mass value="4.1878"/>
      <inertia ixx="14233034E-09" ixy="95885E-09" ixz="-368373E-09" iyy="33518265E-09" iyz="144563E-09" izz="36870672E-09"/>
    </inertial>
    <visual>
      <origin rpy="0 0 0" xyz="0 0 0"/>
      <geometry>
        <mesh filename="package://birdy_v1/meshes//TRUNK.STL"/>
      </geometry>
      <material name="">
        <color rgba="0.79216 0.81961 0.93333 1"/>
      </material>
    </visual>
  </link>
  <link name="link_left_hip1">
    <inertial>
      <origin rpy="0 0 0" xyz="0.0258 0.0003 0.0072"/>
      <mass value="0.4618"/>
      <inertia ixx="526520E-09" ixy="-2600E-09" ixz="-15578E-09" iyy="410196E-09" iyz="-650E-09" izz="288565E-09"/>
    </inertial>
    <visual>
      <origin rpy="0 0 0" xyz="0 0 0"/>
      <geometry>
        <mesh filename="package://birdy_v1/meshes//HIP_ROLL_MOTOR_left.STL"/>
      </geometry>
      <material name="">
        <color rgba="0.752941176470588 0.752941176470588 0.752941176470588 1"/>
      </material>
    </visual>
  </link>
  <joint name="joint_left_hip_yaw" type="revolute">
    <origin rpy="0 0 0" xyz="0.0 -0.061 -0.078"/>
    <parent link="link_trunk"/>
    <child link="link_left_hip1"/>
    <axis xyz="0 0 1"/>
    <limit effort="0" lower="-2.9845105" upper="2.9845105" velocity="0"/>
  </joint>
  <link name="link_left_hip2">
    <inertial>
      <origin rpy="0 0 0" xyz="0.0014  -0.0362 0.0"/>
      <mass value="0.4221"/>
      <inertia ixx="272070E-09" ixy="25300E-09" ixz="-22.5E-09" iyy="401974E-09" iyz="-141E-09" izz="312156E-09"/>
    </inertial>
    <visual>
      <origin rpy="0 0 0" xyz="0 0 0"/>
      <geometry>
        <mesh filename="package://birdy_v1/meshes//HIP_PITCH_MOTOR_left.STL"/>
      </geometry>
      <material name="">
        <color rgba="0.752941176470588 0.752941176470588 0.752941176470588 1"/>
      </material>
    </visual>
  </link>
  <joint name="joint_left_hip_roll" type="revolute">
    <origin rpy="0 0 0" xyz="-0.04 0 0"/>
    <parent link="link_left_hip1"/>
    <child link="link_left_hip2"/>
    <axis xyz="1 0 0"/>
    <limit effort="0" lower="-3.14" upper="3.14" velocity="0"/>
  </joint>
  <link name="link_left_thigh">
    <inertial>
      <origin rpy="0 0 0" xyz="0.0019 -0.0168 -0.0491"/>
      <mass value="1.2707"/>
      <inertia ixx="4720500E-09" ixy="21479E-09" ixz="-188300E-09" iyy="5119350E-09" iyz="-105700E-09" izz="1506438E-09"/>
    </inertial>
    <visual>
      <origin rpy="0 0 0" xyz="0 0 0"/>
      <geometry>
        <mesh filename="package://birdy_v1/meshes//THIGH_left.STL"/>
      </geometry>
      <material name="">
        <color rgba="0.752941176470588 0.752941176470588 0.752941176470588 1"/>
      </material>
    </visual>
  </link>
  <joint name="joint_left_thigh_pitch" type="revolute">
    <origin rpy="0 0 0 " xyz="0 -0.0715 0.0"/>
    <parent link="link_left_hip2"/>
    <child link="link_left_thigh"/>
    <axis xyz="0 1 0"/>
    <limit effort="0" lower="-3.14" upper="3.14" velocity="0"/>
  </joint>
  <link name="link_left_calf">
    <inertial>
      <origin rpy="0 0 0" xyz="0.02422 0.0 -0.103491"/>
      <mass value="0.218165"/>
      <inertia ixx="1353146E-09" ixy="-307E-09" ixz="13829E-09" iyy="1400170E-09" iyz="-624E-09" izz="102949E-09"/>
    </inertial>
    <visual>
      <origin rpy="0 0 0" xyz="0 0 0"/>
      <geometry>
        <mesh filename="package://birdy_v1/meshes//CALF_left.STL"/>
      </geometry>
      <material name="">
        <color rgba="0.752941176470588 0.752941176470588 0.752941176470588 1"/>
      </material>
    </visual>
  </link>
  <joint name="joint_left_calf_pitch" type="revolute">
    <origin rpy="0 0 0" xyz="0 0 -0.20"/>
    <parent link="link_left_thigh"/>
    <child link="link_left_calf"/>
    <axis xyz="0 1 0"/>
    <limit effort="0" lower="-3.14" upper="3.14" velocity="0"/>
  </joint>
  <link name="link_left_foot">
    <inertial>
      <origin rpy="0 0 0" xyz="0.0065 0 -0.044826"/>
      <mass value="0.150205"/>
      <inertia ixx="104290E-09" ixy="-327E-09" ixz="86545E-09" iyy="283559E-09" iyz="-140E-09" izz="209594E-09"/>
    </inertial>
    <visual>
      <origin rpy="0 0 0" xyz="0 0 0"/>
      <geometry>
        <mesh filename="package://birdy_v1/meshes//FOOT_HEEL.STL"/>
      </geometry>
      <material name="">
        <color rgba="0.752941176470588 0.752941176470588 0.752941176470588 1"/>
      </material>
    </visual>
    <visual>
      <origin rpy="0 0 0" xyz="0 0 0"/>
      <geometry>
        <mesh filename="package://birdy_v1/meshes//FOOT_TOE.STL"/>
      </geometry>
      <material name="">
        <color rgba="0.752941176470588 0.752941176470588 0.752941176470588 1"/>
      </material>
    </visual>
    <visual>
      <origin rpy="0 0 0" xyz="0 0 0"/>
      <geometry>
        <mesh filename="package://birdy_v1/meshes//FOOT_SHOE.STL"/>
      </geometry>
      <material name="">
        <color rgba="0.752941176470588 0.752941176470588 0.752941176470588 1"/>
      </material>
    </visual>
  </link>
  <joint name="joint_left_ankle" type="revolute">
    <origin rpy="0 0 0" xyz="0 0 -0.25"/>
    <parent link="link_left_calf"/>
    <child link="link_left_foot"/>
    <axis xyz="0 1 0"/>
    <limit effort="0" lower="-3.14" upper="3.14" velocity="0"/>
  </joint>
  <link name="link_right_hip1">
    <inertial>
      <origin rpy="0 0 0" xyz="0.0258 -0.0003 0.0072"/>
      <mass value="0.4618"/>
      <inertia ixx="526520E-09" ixy="2600E-09" ixz="-15578E-09" iyy="410196E-09" iyz="650E-09" izz="288565E-09"/>
    </inertial>
    <visual>
      <origin rpy="0 0 0" xyz="0 0 0"/>
      <geometry>
        <mesh filename="package://birdy_v1/meshes//HIP_ROLL_MOTOR_right.STL"/>
      </geometry>
      <material name="">
        <color rgba="0.752941176470588 0.752941176470588 0.752941176470588 1"/>
      </material>
    </visual>
  </link>
  <joint name="joint_right_hip_yaw" type="revolute">
    <origin rpy="0 0 0" xyz="0.0  0.061 -0.078"/>
    <parent link="link_trunk"/>
    <child link="link_right_hip1"/>
    <axis xyz="0 0 1"/>
    <limit effort="0" lower="-2.9845105" upper="2.9845105" velocity="0"/>
  </joint>
  <link name="link_right_hip2">
    <inertial>
      <origin rpy="0 0 0" xyz="0.0014 0.0362 0.0"/>
      <mass value="0.4221"/>
      <inertia ixx="272070E-09" ixy="-25300E-09" ixz="22.5E-09" iyy="401974E-09" iyz="-141E-09" izz="312156E-09"/>
    </inertial>
    <visual>
      <origin rpy="0 0 0" xyz="0 0 0"/>
      <geometry>
        <mesh filename="package://birdy_v1/meshes//HIP_PITCH_MOTOR_right.STL"/>
      </geometry>
      <material name="">
        <color rgba="0.752941176470588 0.752941176470588 0.752941176470588 1"/>
      </material>
    </visual>
  </link>
  <joint name="joint_right_hip_roll" type="revolute">
    <origin rpy="0 0 0" xyz="-0.04 0 0"/>
    <parent link="link_right_hip1"/>
    <child link="link_right_hip2"/>
    <axis xyz="1 0 0"/>
    <limit effort="0" lower="-3.14" upper="3.14" velocity="0"/>
  </joint>
  <link name="link_right_thigh">
    <inertial>
      <origin rpy="0 0 0" xyz="0.0019 0.0168 -0.0491"/>
      <mass value="1.2707"/>
      <inertia ixx="4720500E-09" ixy="-21479E-09" ixz="-188300E-09" iyy="5119350E-09" iyz="105700E-09" izz="1506438E-09"/>
    </inertial>
    <visual>
      <origin rpy="0 0 0" xyz="0 0 0"/>
      <geometry>
        <mesh filename="package://birdy_v1/meshes//THIGH_right.STL"/>
      </geometry>
      <material name="">
        <color rgba="0.752941176470588 0.752941176470588 0.752941176470588 1"/>
      </material>
    </visual>
  </link>
  <joint name="joint_right_thigh_pitch" type="revolute">
    <origin rpy="0 0 0 " xyz="0  0.0715 0.0"/>
    <parent link="link_right_hip2"/>
    <child link="link_right_thigh"/>
    <axis xyz="0 1 0"/>
    <limit effort="0" lower="-3.14" upper="3.14" velocity="0"/>
  </joint>
  <link name="link_right_calf">
    <inertial>
      <origin rpy="0 0 0" xyz="0.02422 0.0 -0.103491"/>
      <mass value="0.21302"/>
      <inertia ixx="1353146E-09" ixy="307E-09" ixz="13829E-09" iyy="1400170E-09" iyz="624E-09" izz="102949E-09"/>
    </inertial>
    <visual>
      <origin rpy="0 0 0" xyz="0 0 0"/>
      <geometry>
        <mesh filename="package://birdy_v1/meshes//CALF_right.STL"/>
      </geometry>
      <material name="">
        <color rgba="0.752941176470588 0.752941176470588 0.752941176470588 1"/>
      </material>
    </visual>
  </link>
  <joint name="joint_right_calf_pitch" type="revolute">
    <origin rpy="0 0 0" xyz="0 0 -0.20"/>
    <parent link="link_right_thigh"/>
    <child link="link_right_calf"/>
    <axis xyz="0 1 0"/>
    <limit effort="0" lower="-3.14" upper="3.14" velocity="0"/>
  </joint>
  <link name="link_right_foot">
    <inertial>
      <origin rpy="0 0 0" xyz="0.0065 0 -0.044826"/>
      <mass value="0.150205"/>
      <inertia ixx="104290E-09" ixy="-327E-09" ixz="86545E-09" iyy="283559E-09" iyz="-140E-09" izz="209594E-09"/>
    </inertial>
    <visual>
      <origin rpy="0 0 0" xyz="0 0 0"/>
      <geometry>
        <mesh filename="package://birdy_v1/meshes//FOOT_HEEL.STL"/>
      </geometry>
      <material name="">
        <color rgba="0.752941176470588 0.752941176470588 0.752941176470588 1"/>
      </material>
    </visual>
    <visual>
      <origin rpy="0 0 0" xyz="0 0 0"/>
      <geometry>
        <mesh filename="package://birdy_v1/meshes//FOOT_TOE.STL"/>
      </geometry>
      <material name="">
        <color rgba="0.752941176470588 0.752941176470588 0.752941176470588 1"/>
      </material>
    </visual>
    <visual>
      <origin rpy="0 0 0" xyz="0 0 0"/>
      <geometry>
        <mesh filename="package://birdy_v1/meshes//FOOT_SHOE.STL"/>
      </geometry>
      <material name="">
        <color rgba="0.752941176470588 0.752941176470588 0.752941176470588 1"/>
      </material>
    </visual>
  </link>
  <joint name="joint_right_ankle" type="revolute">
    <origin rpy="0 0 0" xyz="0 0 -0.25"/>
    <parent link="link_right_calf"/>
    <child link="link_right_foot"/>
    <axis xyz="0 1 0"/>
    <limit effort="0" lower="-3.14" upper="3.14" velocity="0"/>
  </joint>

  <link name="link_arm_yaw_motor">
    <inertial>
      <origin rpy="0 0 0" xyz="0.001 -0.0004 -0.0193"/>
      <mass value="0.3869"/>
      <inertia ixx="232068E-09" ixy="81E-09" ixz="-302E-09" iyy="244432E-09" iyz="-3117E-09" izz="339832E-09"/>
    </inertial>
    <visual>
      <origin rpy="0 0 0" xyz="0 0 0"/>
      <geometry>
        <mesh filename="package://birdy_v1/meshes//ARM_YAW_MOTOR.STL"/>
      </geometry>
      <material name="">
        <color rgba="0.752941176470588 0.752941176470588 0.752941176470588 1"/>
      </material>
    </visual>
  </link>
  <joint name="joint_base_fixed" type="fixed">
    <origin rpy="0 0 0" xyz="0.0 0 0.078"/>
    <parent link="link_trunk"/>
    <child link="link_arm_yaw_motor"/>
    <axis xyz="0 0 1"/>
    <limit effort="0" lower="-2" upper="2" velocity="0"/>
  </joint>
  <link name="link_arm_pitch_motor">
    <inertial>
      <origin rpy="0 0 0" xyz="0.0 -0.0041 -0.0018"/>
      <mass value="0.4377"/>
      <inertia ixx="301263E-09" ixy="208E-09" ixz="234E-09" iyy="417629E-09" iyz="-3328E-09" izz="273852E-09"/>
    </inertial>
    <visual>
      <origin rpy="0 0 0" xyz="0 0 0"/>
      <geometry>
        <mesh filename="package://birdy_v1/meshes//ARM_PITCH_MOTOR.STL"/>
      </geometry>
      <material name="">
        <color rgba="0.752941176470588 0.752941176470588 0.752941176470588 1"/>
      </material>
    </visual>
  </link>
  <joint name="joint_shoulder_yaw" type="revolute">
    <origin rpy="0 0 0" xyz="0 0 0.05"/>
    <parent link="link_arm_yaw_motor"/>
    <child link="link_arm_pitch_motor"/>
    <axis xyz="0 0 1"/>
    <limit effort="0" lower="-2" upper="2" velocity="0"/>
  </joint>
  <link name="link_arm_lower">
    <inertial>
      <origin rpy="0 0 0" xyz="-0.0098 0.0043 -0.1525"/>
      <mass value="0.6706"/>
      <inertia ixx="3815212E-09" ixy="21501E-09" ixz="-327614E-09" iyy="4196055E-09" iyz="114174E-09" izz="582055E-09"/>
    </inertial>
    <visual>
      <origin rpy="0 0 0" xyz="0 0 0"/>
      <geometry>
        <mesh filename="package://birdy_v1/meshes//ARM_LOWER.STL"/>
      </geometry>
      <material name="">
        <color rgba="0.752941176470588 0.752941176470588 0.752941176470588 1"/>
      </material>
    </visual>
  </link>
  <joint name="joint_shoulder_pitch" type="revolute">
    <origin rpy="0 0 0" xyz="0 0 0"/>
    <parent link="link_arm_pitch_motor"/>
    <child link="link_arm_lower"/>
    <axis xyz="0 1 0"/>
    <limit effort="0" lower="-2" upper="2" velocity="0"/>
  </joint>
  <link name="link_arm_upper">
    <inertial>
      <origin rpy="0 0 0" xyz="-0.0088 -0.0027 0.2385"/>
      <mass value="0.8447"/>
      <inertia ixx="15821722E-09" ixy="-21885E-09" ixz="1399914E-09" iyy="16373036E-09" iyz="-114650E-09" izz="856969E-09"/>
    </inertial>
    <visual>
      <origin rpy="0 0 0" xyz="0 0 0"/>
      <geometry>
        <mesh filename="package://birdy_v1/meshes//ARM_UPPER.STL"/>
      </geometry>
      <material name="">
        <color rgba="0.752941176470588 0.752941176470588 0.752941176470588 1"/>
      </material>
    </visual>
  </link>
  <joint name="joint_elbow_pitch" type="revolute">
    <origin rpy="0 0 0" xyz="0 0 -0.2"/>
    <parent link="link_arm_lower"/>
    <child link="link_arm_upper"/>
    <axis xyz="0 1 0"/>
    <limit effort="0" lower="-2" upper="2" velocity="0"/>
  </joint>
  <link name="link_arm_end">
    <inertial>
      <origin rpy="0 0 0" xyz="-0.0481 0.0043 0.0121"/>
      <mass value="0.1228"/>
      <inertia ixx="109814E-09" ixy="26439E-09" ixz="-13472E-09" iyy="184335E-09" iyz="-6657E-09" izz="204264E-09"/>
    </inertial>
    <visual>
      <origin rpy="0 0 0" xyz="0 0 0"/>
      <geometry>
        <mesh filename="package://birdy_v1/meshes//ARM_END.STL"/>
      </geometry>
      <material name="">
        <color rgba="0.752941176470588 0.752941176470588 0.752941176470588 1"/>
      </material>
    </visual>
  </link>
  <joint name="joint_wrist_pitch" type="revolute">
    <origin rpy="0 0 0" xyz="0 0 0.35"/>
    <parent link="link_arm_upper"/>
    <child link="link_arm_end"/>
    <axis xyz="0 1 0"/>
    <limit effort="0" lower="-2" upper="2" velocity="0"/>
  </joint>
  <link name="dummy_arm_ee">
  </link>
  <joint name="joint_arm_ee_fixed" type="fixed">
    <origin rpy="0 0 0" xyz="0 0 0"/>
    <parent link="link_arm_end"/>
    <child link="dummy_arm_ee"/>
  </joint>
</robot>

