<?xml version="1.0" ?>
<!-- =================================================================================== -->
<!-- |    This document was autogenerated by xacro from birdy_v1_L.xacro             | -->
<!-- |    EDITING THIS FILE BY HAND IS NOT RECOMMENDED                                 | -->
<!-- =================================================================================== -->
<robot name="birdy_v1_L">
<!--<link name="world">
</link>-->
<!--<joint name="joint_fixed_world" type="floating">
  <origin rpy="0 0 0" xyz="0 0 0.65"/>
  <parent link="world"/>
  <child link="link_trunk"/>
</joint>-->
  <link name="link_trunk">
    <inertial>
      <origin rpy="0 0 0" xyz="0.145 0 0.0274"/>
      <mass value="4.4369"/>
      <inertia ixx="17052550E-09" ixy="-17322E-09" ixz="-787313E-09" iyy="33900769E-09" iyz="-54759E-09" izz="37138656E-09"/>
    </inertial>
    <visual>
      <origin rpy="0 0 0" xyz="0 0 0"/>
      <geometry>
        <mesh filename="package://birdy_v1/meshes//TRUNK_LOWER_LIMB.STL"/>
      </geometry>
      <material name="">
        <color rgba="0.79216 0.81961 0.93333 1"/>
      </material>
    </visual>
  </link>
  <link name="link_left_hip1">
    <inertial>
      <origin rpy="0 0 0" xyz="0.0258 0.0003 0.0072"/>
      <mass value="0.4618"/>
      <inertia ixx="526520E-09" ixy="-2600E-09" ixz="-15578E-09" iyy="410196E-09" iyz="-650E-09" izz="288565E-09"/>
    </inertial>
    <visual>
      <origin rpy="0 0 0" xyz="0 0 0"/>
      <geometry>
        <mesh filename="package://birdy_v1/meshes//HIP_ROLL_MOTOR_left.STL"/>
      </geometry>
      <material name="">
        <color rgba="0.752941176470588 0.752941176470588 0.752941176470588 1"/>
      </material>
    </visual>
  </link>
  <joint name="joint_left_hip_yaw" type="revolute">
    <origin rpy="0 0 0" xyz="0.0 -0.061 -0.078"/>
    <parent link="link_trunk"/>
    <child link="link_left_hip1"/>
    <axis xyz="0 0 1"/>
    <limit effort="0" lower="-2.9845105" upper="2.9845105" velocity="0"/>
  </joint>
  <link name="link_left_hip2">
    <inertial>
      <origin rpy="0 0 0" xyz="0.0014  -0.0362 0.0"/>
      <mass value="0.4221"/>
      <inertia ixx="272070E-09" ixy="25300E-09" ixz="-22.5E-09" iyy="401974E-09" iyz="-141E-09" izz="312156E-09"/>
    </inertial>
    <visual>
      <origin rpy="0 0 0" xyz="0 0 0"/>
      <geometry>
        <mesh filename="package://birdy_v1/meshes//HIP_PITCH_MOTOR_left.STL"/>
      </geometry>
      <material name="">
        <color rgba="0.752941176470588 0.752941176470588 0.752941176470588 1"/>
      </material>
    </visual>
  </link>
  <joint name="joint_left_hip_roll" type="revolute">
    <origin rpy="0 0 0" xyz="-0.04 0 0"/>
    <parent link="link_left_hip1"/>
    <child link="link_left_hip2"/>
    <axis xyz="1 0 0"/>
    <limit effort="0" lower="-3.14" upper="3.14" velocity="0"/>
  </joint>
  <link name="link_left_thigh">
    <inertial>
      <origin rpy="0 0 0" xyz="0.0019 -0.0168 -0.0491"/>
      <mass value="1.2707"/>
      <inertia ixx="4720500E-09" ixy="21479E-09" ixz="-188300E-09" iyy="5119350E-09" iyz="-105700E-09" izz="1506438E-09"/>
    </inertial>
    <visual>
      <origin rpy="0 0 0" xyz="0 0 0"/>
      <geometry>
        <mesh filename="package://birdy_v1/meshes//THIGH_left.STL"/>
      </geometry>
      <material name="">
        <color rgba="0.752941176470588 0.752941176470588 0.752941176470588 1"/>
      </material>
    </visual>
  </link>
  <joint name="joint_left_thigh_pitch" type="revolute">
    <origin rpy="0 0 0 " xyz="0 -0.0715 0.0"/>
    <parent link="link_left_hip2"/>
    <child link="link_left_thigh"/>
    <axis xyz="0 1 0"/>
    <limit effort="0" lower="-3.14" upper="3.14" velocity="0"/>
  </joint>
  <link name="link_left_calf">
    <inertial>
      <origin rpy="0 0 0" xyz="0.02422 0.0 -0.103491"/>
      <mass value="0.218165"/>
      <inertia ixx="1353146E-09" ixy="-307E-09" ixz="13829E-09" iyy="1400170E-09" iyz="-624E-09" izz="102949E-09"/>
    </inertial>
    <visual>
      <origin rpy="0 0 0" xyz="0 0 0"/>
      <geometry>
        <mesh filename="package://birdy_v1/meshes//CALF_left.STL"/>
      </geometry>
      <material name="">
        <color rgba="0.752941176470588 0.752941176470588 0.752941176470588 1"/>
      </material>
    </visual>
  </link>
  <joint name="joint_left_calf_pitch" type="revolute">
    <origin rpy="0 0 0" xyz="0 0 -0.20"/>
    <parent link="link_left_thigh"/>
    <child link="link_left_calf"/>
    <axis xyz="0 1 0"/>
    <limit effort="0" lower="-3.14" upper="3.14" velocity="0"/>
  </joint>
  <link name="link_left_foot">
    <inertial>
      <origin rpy="0 0 0" xyz="0.0065 0 -0.044826"/>
      <mass value="0.150205"/>
      <inertia ixx="104290E-09" ixy="-327E-09" ixz="86545E-09" iyy="283559E-09" iyz="-140E-09" izz="209594E-09"/>
    </inertial>
    <visual>
      <origin rpy="0 0 0" xyz="0 0 0"/>
      <geometry>
        <mesh filename="package://birdy_v1/meshes//FOOT_HEEL.STL"/>
      </geometry>
      <material name="">
        <color rgba="0.752941176470588 0.752941176470588 0.752941176470588 1"/>
      </material>
    </visual>
    <visual>
      <origin rpy="0 0 0" xyz="0 0 0"/>
      <geometry>
        <mesh filename="package://birdy_v1/meshes//FOOT_TOE.STL"/>
      </geometry>
      <material name="">
        <color rgba="0.752941176470588 0.752941176470588 0.752941176470588 1"/>
      </material>
    </visual>
    <visual>
      <origin rpy="0 0 0" xyz="0 0 0"/>
      <geometry>
        <mesh filename="package://birdy_v1/meshes//FOOT_SHOE.STL"/>
      </geometry>
      <material name="">
        <color rgba="0.752941176470588 0.752941176470588 0.752941176470588 1"/>
      </material>
    </visual>
  </link>
  <joint name="joint_left_ankle" type="revolute">
    <origin rpy="0 0 0" xyz="0 0 -0.25"/>
    <parent link="link_left_calf"/>
    <child link="link_left_foot"/>
    <axis xyz="0 1 0"/>
    <limit effort="0" lower="-3.14" upper="3.14" velocity="0"/>
  </joint>
  <link name="link_right_hip1">
    <inertial>
      <origin rpy="0 0 0" xyz="0.0258 -0.0003 0.0072"/>
      <mass value="0.4618"/>
      <inertia ixx="526520E-09" ixy="2600E-09" ixz="-15578E-09" iyy="410196E-09" iyz="650E-09" izz="288565E-09"/>
    </inertial>
    <visual>
      <origin rpy="0 0 0" xyz="0 0 0"/>
      <geometry>
        <mesh filename="package://birdy_v1/meshes//HIP_ROLL_MOTOR_right.STL"/>
      </geometry>
      <material name="">
        <color rgba="0.752941176470588 0.752941176470588 0.752941176470588 1"/>
      </material>
    </visual>
  </link>
  <joint name="joint_right_hip_yaw" type="revolute">
    <origin rpy="0 0 0" xyz="0.0  0.061 -0.078"/>
    <parent link="link_trunk"/>
    <child link="link_right_hip1"/>
    <axis xyz="0 0 1"/>
    <limit effort="0" lower="-2.9845105" upper="2.9845105" velocity="0"/>
  </joint>
  <link name="link_right_hip2">
    <inertial>
      <origin rpy="0 0 0" xyz="0.0014 0.0362 0.0"/>
      <mass value="0.4221"/>
      <inertia ixx="272070E-09" ixy="-25300E-09" ixz="22.5E-09" iyy="401974E-09" iyz="-141E-09" izz="312156E-09"/>
    </inertial>
    <visual>
      <origin rpy="0 0 0" xyz="0 0 0"/>
      <geometry>
        <mesh filename="package://birdy_v1/meshes//HIP_PITCH_MOTOR_right.STL"/>
      </geometry>
      <material name="">
        <color rgba="0.752941176470588 0.752941176470588 0.752941176470588 1"/>
      </material>
    </visual>
  </link>
  <joint name="joint_right_hip_roll" type="revolute">
    <origin rpy="0 0 0" xyz="-0.04 0 0"/>
    <parent link="link_right_hip1"/>
    <child link="link_right_hip2"/>
    <axis xyz="1 0 0"/>
    <limit effort="0" lower="-3.14" upper="3.14" velocity="0"/>
  </joint>
  <link name="link_right_thigh">
    <inertial>
      <origin rpy="0 0 0" xyz="0.0019 0.0168 -0.0491"/>
      <mass value="1.2707"/>
      <inertia ixx="4720500E-09" ixy="-21479E-09" ixz="-188300E-09" iyy="5119350E-09" iyz="105700E-09" izz="1506438E-09"/>
    </inertial>
    <visual>
      <origin rpy="0 0 0" xyz="0 0 0"/>
      <geometry>
        <mesh filename="package://birdy_v1/meshes//THIGH_right.STL"/>
      </geometry>
      <material name="">
        <color rgba="0.752941176470588 0.752941176470588 0.752941176470588 1"/>
      </material>
    </visual>
  </link>
  <joint name="joint_right_thigh_pitch" type="revolute">
    <origin rpy="0 0 0 " xyz="0  0.0715 0.0"/>
    <parent link="link_right_hip2"/>
    <child link="link_right_thigh"/>
    <axis xyz="0 1 0"/>
    <limit effort="0" lower="-3.14" upper="3.14" velocity="0"/>
  </joint>
  <link name="link_right_calf">
    <inertial>
      <origin rpy="0 0 0" xyz="0.02422 0.0 -0.103491"/>
      <mass value="0.21302"/>
      <inertia ixx="1353146E-09" ixy="307E-09" ixz="13829E-09" iyy="1400170E-09" iyz="624E-09" izz="102949E-09"/>
    </inertial>
    <visual>
      <origin rpy="0 0 0" xyz="0 0 0"/>
      <geometry>
        <mesh filename="package://birdy_v1/meshes//CALF_right.STL"/>
      </geometry>
      <material name="">
        <color rgba="0.752941176470588 0.752941176470588 0.752941176470588 1"/>
      </material>
    </visual>
  </link>
  <joint name="joint_right_calf_pitch" type="revolute">
    <origin rpy="0 0 0" xyz="0 0 -0.20"/>
    <parent link="link_right_thigh"/>
    <child link="link_right_calf"/>
    <axis xyz="0 1 0"/>
    <limit effort="0" lower="-3.14" upper="3.14" velocity="0"/>
  </joint>
  <link name="link_right_foot">
    <inertial>
      <origin rpy="0 0 0" xyz="0.0065 0 -0.044826"/>
      <mass value="0.150205"/>
      <inertia ixx="104290E-09" ixy="-327E-09" ixz="86545E-09" iyy="283559E-09" iyz="-140E-09" izz="209594E-09"/>
    </inertial>
    <visual>
      <origin rpy="0 0 0" xyz="0 0 0"/>
      <geometry>
        <mesh filename="package://birdy_v1/meshes//FOOT_HEEL.STL"/>
      </geometry>
      <material name="">
        <color rgba="0.752941176470588 0.752941176470588 0.752941176470588 1"/>
      </material>
    </visual>
    <visual>
      <origin rpy="0 0 0" xyz="0 0 0"/>
      <geometry>
        <mesh filename="package://birdy_v1/meshes//FOOT_TOE.STL"/>
      </geometry>
      <material name="">
        <color rgba="0.752941176470588 0.752941176470588 0.752941176470588 1"/>
      </material>
    </visual>
    <visual>
      <origin rpy="0 0 0" xyz="0 0 0"/>
      <geometry>
        <mesh filename="package://birdy_v1/meshes//FOOT_SHOE.STL"/>
      </geometry>
      <material name="">
        <color rgba="0.752941176470588 0.752941176470588 0.752941176470588 1"/>
      </material>
    </visual>
  </link>
  <joint name="joint_right_ankle" type="revolute">
    <origin rpy="0 0 0" xyz="0 0 -0.25"/>
    <parent link="link_right_calf"/>
    <child link="link_right_foot"/>
    <axis xyz="0 1 0"/>
    <limit effort="0" lower="-3.14" upper="3.14" velocity="0"/>
  </joint>
</robot>

