<?xml version="1.0" encoding="utf-8"?>
<!-- This URDF was automatically created by SolidWorks to URDF Exporter! Originally created by Stephen Brawner (brawner@gmail.com) 
     Commit Version: 1.6.0-4-g7f85cfe  Build Version: 1.6.7995.38578
     For more information, please see http://wiki.ros.org/sw_urdf_exporter -->
<robot
  name="biped_s5">
  <link
    name="torso">
    <inertial>
      <origin 
        	xyz = "0.0 -0.0 0.13783251" 
          rpy="0 0 0" />
      <mass value="27.08245" />
      <inertia 
        ixx="0.39641171" 
        ixy="0.00" 
        ixz="0.00" 
        iyy="0.37105636" 
        iyz="-0.00" 
        izz="0.16013351" />
     </inertial>
    <!-- <inertial>
      <origin 
        	xyz = "-0.01954581 -0.0024237 0.13783251" 
          rpy="0 0 0" />
      <mass value="27.08245" />
      <inertia 
        ixx="0.39641171" 
        ixy="0.00029286" 
        ixz="0.05364597" 
        iyy="0.37105636" 
        iyz="-0.00016709" 
        izz="0.16013351" />
    </inertial> -->
    <visual>
      <origin
        xyz="0 0 0"
        rpy="0 0 0" />
      <geometry>
        <mesh
          filename="../meshes/torso.STL" />
      </geometry>
      <material
        name="">
        <color
          rgba="0.890196078431372 0.890196078431372 0.913725490196078 1" />
      </material>
    </visual>
    <collision>
      <origin
        xyz="0 0 0"
        rpy="0 0 0" />
      <geometry>
        <mesh
          filename="../meshes/torso.STL" />
      </geometry>
    </collision>
  </link>
  <link
    name="l_leg_roll">
    <inertial>
      <origin
        xyz="-0.00362787 0.0 -0.00362787"
        rpy="0 0 0" />
      <mass
        value="1.854" />
      <inertia
        ixx="0.00220007"
        ixy="-0.00000109"
        ixz="-0.00001907"
        iyy="0.00309841"
        iyz="0.00000000"
        izz="0.00414137" />
    </inertial>
    <visual>
      <origin
        xyz="0 0 0"
        rpy="0 0 0" />
      <geometry>
        <mesh
          filename="../meshes/l_leg_roll.STL" />
      </geometry>
      <material
        name="">
        <color
          rgba="0.890196078431372 0.890196078431372 0.913725490196078 1" />
      </material>
    </visual>
    <!-- <collision>
      <origin
        xyz="0 0 0"
        rpy="0 0 0" />
      <geometry>
        <mesh
          filename="../meshes/l_leg_roll.STL" />
      </geometry>
    </collision> -->
  </link>
  <joint
    name="l_leg_roll"
    type="revolute">
    <origin
      xyz="-0.00249999999964622 0.0869999999999562 -0.0660000000049241"
      rpy="0 0 0" />
    <parent
      link="torso" />
    <child
      link="l_leg_roll" />
    <axis
      xyz="1 0 0" />
    <limit 
      lower="-0.3" upper="0.64" effort="200" velocity="14" />
  </joint>
  <!-- <transmission type="SimpleTransmission">
    <joint name="l_leg_roll" />
    <actuator name="l_leg_roll_motor" />
  </transmission> -->
  <link
    name="l_leg_yaw">
    <inertial>
      <origin
        xyz="-0.000000 0.00487083 -0.06699331"
        rpy="0 0 0" />
      <mass
        value="0.358" />
      <inertia
        ixx="0.00299812"
        ixy="0.00000002"
        ixz="0.00000002"
        iyy="0.00217705"
        iyz="0.00001436"
        izz="0.00112966" />
    </inertial>
    <visual>
      <origin
        xyz="0 0 0"
        rpy="0 0 0" />
      <geometry>
        <mesh
          filename="../meshes/l_leg_yaw.STL" />
      </geometry>
      <material
        name="">
        <color
          rgba="0.890196078431372 0.890196078431372 0.913725490196078 1" />
      </material>
    </visual>
    <!-- <collision>
      <origin
        xyz="0 0 0"
        rpy="0 0 0" />
      <geometry>
        <mesh
          filename="../meshes/l_leg_yaw.STL" />
      </geometry>
    </collision> -->
  </link>
  <joint
    name="l_leg_yaw"
    type="revolute">
    <origin
      xyz="0 0 0"
      rpy="0 0 0" />
    <parent
      link="l_leg_roll" />
    <child
      link="l_leg_yaw" />
    <axis
      xyz="0 0 1" />
    <limit 
      lower="-1.02" upper="0.51" effort="100" velocity="14" />
  </joint>
  <!-- <transmission type="SimpleTransmission">
    <joint 
      name="l_leg_yaw" />
    <actuator name="l_leg_yaw_motor" />
  </transmission> -->
  <link
    name="l_leg_pitch">
    <inertial>
      <origin
        xyz="0.00593672 0.00193220 -0.09495981"
        rpy="0 0 0" />
      <mass
        value="6.094" />
        <inertia
        ixx="0.13350217"
        ixy="0.00032336"
        ixz="0.01086639"
        iyy="0.13643554"
        iyz="0.00140170"
        izz="0.01383057" />
      <!-- <inertia
        ixx="0.13350217"
        ixy="-0.00032336"
        ixz="-0.01086639"
        iyy="0.13643554"
        iyz="-0.00140170"
        izz="0.01383057" /> -->
    </inertial>
    <visual>
      <origin
        xyz="0 0 0"
        rpy="0 0 0" />
      <geometry>
        <mesh
          filename="../meshes/l_leg_pitch.STL" />
      </geometry>
      <material
        name="">
        <color
          rgba="0.890196078431372 0.890196078431372 0.913725490196078 1" />
      </material>
    </visual>
    <!-- <collision>
      <origin
        xyz="0 0 0"
        rpy="0 0 0" />
      <geometry>
        <mesh
          filename="../meshes/l_leg_pitch.STL" />
      </geometry>
    </collision> -->
  </link>
  <joint
    name="l_leg_pitch"
    type="revolute">
    <origin
      xyz="0 0 -0.124999999999996"
      rpy="0 0 0" />
    <parent
      link="l_leg_yaw" />
    <child
      link="l_leg_pitch" />
    <axis
      xyz="0 1 0" />
    <limit 
      lower="-1.785" upper="1.02" effort="200" velocity="14" />
  </joint>
  <!-- <transmission type="SimpleTransmission">
    <joint name="l_leg_pitch" />
    <actuator name="l_leg_pitch_motor" />
  </transmission> -->
  <link
    name="l_knee">
    <inertial>
      <origin
        xyz="0.00131184 -0.00020666 -0.15764775"
        rpy="0 0 0" />
      <mass
        value="1.968" />
      <inertia
        ixx="0.07729951"
        ixy="-0.00000209"
        ixz="-0.00005535"
        iyy="0.07755289"
        iyz="0.00028214"
        izz="0.00121468" />
    </inertial>
    <visual>
      <origin
        xyz="0 0 0"
        rpy="0 0 0" />
      <geometry>
        <mesh
          filename="../meshes/l_knee.STL" />
      </geometry>
      <material
        name="">
        <color
          rgba="0.890196078431372 0.890196078431372 0.913725490196078 1" />
      </material>
    </visual>
    <!-- <collision>
      <origin
        xyz="0 0 0"
        rpy="0 0 0" />
      <geometry>
        <mesh
          filename="../meshes/l_knee.STL" />
      </geometry>
    </collision> -->
  </link>
  <joint
    name="l_knee"
    type="revolute">
    <origin
      xyz="0.0419999999999991 0 -0.371446748811991"
      rpy="0 0 0" />
    <parent
      link="l_leg_pitch" />
    <child
      link="l_knee" />
    <axis
      xyz="0 1 0" />
    <limit 
      lower="-0.1" upper="1.95" effort="200" velocity="14" />
  </joint>
  <!-- <transmission type="SimpleTransmission">
    <joint name="l_knee" />
    <actuator name="l_knee_motor" />
  </transmission> -->
  <link
    name="l_foot_pitch">
    <inertial>
      <origin
        xyz="2.20870565816045E-07 2.20870038855625E-07 3.99680288865056E-15"
        rpy="0 0 0" />
      <mass
        value="0.071" />
      <inertia
        ixx="8.65317607419046E-10"
        ixy="4.38657784850507E-19"
        ixz="-3.49395618885217E-14"
        iyy="8.65317607419047E-10"
        iyz="3.54041160030983E-14"
        izz="1.52218316128677E-09" />
    </inertial>
    <visual>
      <origin
        xyz="0 0 0"
        rpy="0 0 0" />
      <geometry>
        <mesh
          filename="../meshes/l_foot_pitch.STL" />
      </geometry>
      <material
        name="">
        <color
          rgba="0.890196078431372 0.890196078431372 0.913725490196078 1" />
      </material>
    </visual>
    <!-- <collision>
      <origin
        xyz="0 0 0"
        rpy="0 0 0" />
      <geometry>
        <mesh
          filename="../meshes/l_foot_pitch.STL" />
      </geometry>
    </collision> -->
  </link>
  <joint
    name="l_foot_pitch"
    type="revolute">
    <origin
      xyz="0 0 -0.446000000000003"
      rpy="0 0 0" />
    <parent
      link="l_knee" />
    <child
      link="l_foot_pitch" />
    <axis
      xyz="0 1 0" />
    <limit 
      lower="-0.7" upper="0.7" effort="70" velocity="10" />
  </joint>
  <link
    name="l_foot_roll">
    <inertial>
      <origin
        xyz="-0.00253564517573878 -8.27076149374772E-06 -0.0377214610795236"
        rpy="0 0 0" />
      <mass
        value="0.302" />
      <inertia
        ixx="0.000124764774157541"
        ixy="2.03584836681097E-08"
        ixz="5.85765890399589E-06"
        iyy="0.000552202150208444"
        iyz="1.48966647988658E-08"
        izz="0.000647202075206351" />
    </inertial>
    <visual>
      <origin
        xyz="0 0 0"
        rpy="0 0 0" />
      <geometry>
        <mesh
          filename="../meshes/l_foot_roll.STL" />
      </geometry>
      <material
        name="">
        <color
          rgba="0.890196078431372 0.890196078431372 0.913725490196078 1" />
      </material>
    </visual>
    <collision>
      <origin
        xyz="0 0 0"
        rpy="0 0 0" />
      <geometry>
        <mesh
          filename="../meshes/l_foot_roll.STL" />
      </geometry>
    </collision>
    <visual>
      <origin rpy="0 0 0" xyz="-0.075 0.03 -0.055" />
      <geometry>
        <sphere radius="0.005" />
      </geometry>
    </visual>
    <collision>
      <origin rpy="0 0 0" xyz="-0.075 0.03 -0.055" />
      <geometry>
        <sphere radius="0.005" />
      </geometry>
    </collision>
    <visual>
      <origin rpy="0 0 0" xyz="-0.075 -0.03 -0.055" />
      <geometry>
        <sphere radius="0.005" />
      </geometry>
    </visual>
    <collision>
      <origin rpy="0 0 0" xyz="-0.075 -0.03 -0.055" />
      <geometry>
        <sphere radius="0.005" />
      </geometry>
    </collision>

    <visual>
      <origin rpy="0 0 0" xyz="0.075 0.03 -0.055" />
      <geometry>
        <sphere radius="0.005" />
      </geometry>
    </visual>
    <collision>
      <origin rpy="0 0 0" xyz="0.075 0.03 -0.055" />
      <geometry>
        <sphere radius="0.005" />
      </geometry>
    </collision>
    <visual>
      <origin rpy="0 0 0" xyz="0.075 -0.03 -0.055" />
      <geometry>
        <sphere radius="0.005" />
      </geometry>
    </visual>
    <collision>
      <origin rpy="0 0 0" xyz="0.075 -0.03 -0.055" />
      <geometry>
        <sphere radius="0.005" />
      </geometry>
    </collision>
  </link>
  <joint
    name="l_foot_roll"
    type="revolute">
    <origin
      xyz="0 0 0"
      rpy="0 0 0" />
    <parent
      link="l_foot_pitch" />
    <child
      link="l_foot_roll" />
    <axis
      xyz="1 0 0" />
    <limit 
      lower="-0.51" upper="0.51" effort="70" velocity="10" />
  </joint>
  <frame link="l_foot_roll" name="l_foot_roll_l_frame" xyz="-0.0563 0.025 0.01473" />
  <frame link="l_foot_roll" name="l_foot_roll_r_frame" xyz="-0.0563 -0.025 0.01473" />
  <!-- <link
    name="l_l_bar">
    <inertial>
      <origin
        xyz="-0.016687787283582 0.00762416259674127 0.00446874072339742"
        rpy="0 0 0" />
      <mass
        value="0.024" />
      <inertia
        ixx="3.76376925130472E-06"
        ixy="-1.60355873085232E-06"
        ixz="2.75422428121363E-06"
        iyy="1.63385621482581E-05"
        iyz="4.29191184080558E-07"
        izz="1.33162944793119E-05" />
    </inertial>
    <visual>
      <origin
        xyz="0 0 0"
        rpy="0 0 0" />
      <geometry>
        <mesh
          filename="../meshes/l_l_bar.STL" />
      </geometry>
      <material
        name="">
        <color
          rgba="0.890196078431372 0.890196078431372 0.913725490196078 1" />
      </material>
    </visual>
    <collision>
      <origin
        xyz="0 0 0"
        rpy="0 0 0" />
      <geometry>
        <mesh
          filename="../meshes/l_l_bar.STL" />
      </geometry>
    </collision>
  </link> -->
  <!-- <joint
    name="l_l_bar"
    type="fixed">
    <origin
      xyz="0 0.0250000000000088 -0.0900000000000168"
      rpy="0 0 0" />
    <parent
      link="l_knee" />
    <child
      link="l_l_bar" />
    <axis
      xyz="0 1 0" />
    <limit lower="-1.58" upper="0.50" effort="74" elocity="47" />
  </joint> -->
  <!-- <transmission type="SimpleTransmission">
    <joint name="l_l_bar" />
    <actuator name="l_l_bar_motor">    
      <drake:gear_ratio value="10.0" />
      <drake:rotor_inertia value="0.0001002" />
    </actuator>
  </transmission> -->
  <!-- <link
    name="l_l_tendon">
    <inertial>
      <origin
        xyz="-0.000597102791892887 -5.48291770866016E-05 -0.182364861842155"
        rpy="0 0 0" />
      <mass
        value="0.088" />
      <inertia
        ixx="0.00020807802516773"
        ixy="-1.37273804297484E-11"
        ixz="-4.87712605073332E-08"
        iyy="0.000207622111191351"
        iyz="-4.82828354402287E-08"
        izz="1.17120009168066E-06" />
    </inertial>
    <visual>
      <origin
        xyz="0 0 0"
        rpy="0 0 0" />
      <geometry>
        <mesh
          filename="../meshes/l_l_tendon.STL" />
      </geometry>
      <material
        name="">
        <color
          rgba="0.890196078431372 0.890196078431372 0.913725490196078 1" />
      </material>
    </visual>
    <collision>
      <origin
        xyz="0 0 0"
        rpy="0 0 0" />
      <geometry>
        <mesh
          filename="../meshes/l_l_tendon.STL" />
      </geometry>
    </collision>
  </link> -->
  <!-- <joint
    name="l_l_tendon"
    type="fixed">
    <origin
      xyz="-0.0560272920021761 0 0.0149980849078144"
      rpy="0 0 0" />
    <parent
      link="l_l_bar" />
    <child
      link="l_l_tendon" />
    <axis
      xyz="0 1 0" />
  </joint> -->
  <!-- <drake:joint 
    name="l_l_tendon" 
    type="universal">
    <origin 
      xyz="-0.0560267814521323 0 0.0149999920038312" 
      rpy="0 0 0" />
    <parent 
      link="l_l_bar" />
    <child 
      link="l_l_tendon" />
  </drake:joint> -->
  <!-- <frame link="l_l_tendon" name="l_l_tendon_frame" xyz="0 0 -0.3563" /> -->
  <!-- <link
    name="l_r_bar">
    <inertial>
      <origin
        xyz="-0.0166882601701992 -0.00762416103555331 0.00446699687351448"
        rpy="0 0 0" />
      <mass
        value="0.024" />
      <inertia
        ixx="3.7644064576205E-06"
        ixy="1.60349417651119E-06"
        ixz="2.75532750456472E-06"
        iyy="1.63385611092457E-05"
        iyz="-4.29429893697695E-07"
        izz="1.33156559001003E-05" />
    </inertial>
    <visual>
      <origin
        xyz="0 0 0"
        rpy="0 0 0" />
      <geometry>
        <mesh
          filename="../meshes/l_r_bar.STL" />
      </geometry>
      <material
        name="">
        <color
          rgba="0.890196078431372 0.890196078431372 0.913725490196078 1" />
      </material>
    </visual>
    <collision>
      <origin
        xyz="0 0 0"
        rpy="0 0 0" />
      <geometry>
        <mesh
          filename="../meshes/l_r_bar.STL" />
      </geometry>
    </collision>
  </link> -->
  <!-- <joint
    name="l_r_bar"
    type="fixed">
    <origin
      xyz="0 -0.0249999999999929 -0.155000000000017"
      rpy="0 0 0" />
    <parent
      link="l_knee" />
    <child
      link="l_r_bar" />
    <axis
      xyz="0 1 0" />
  </joint> -->
  <!-- <transmission type="SimpleTransmission">
    <joint name="l_r_bar" />
    <actuator name="l_r_bar_motor">
      <drake:gear_ratio value="10.0" />
      <drake:rotor_inertia value="0.0001002" />
    </actuator>
  </transmission> -->
  <!-- <link
    name="l_r_tendon">
    <inertial>
      <origin
        xyz="-0.000605902956738801 6.3248961663584E-05 -0.150985512649844"
        rpy="0 0 0" />
      <mass
        value="0.102" />
      <inertia
        ixx="0.000364220218547287"
        ixy="1.26888748481225E-11"
        ixz="-6.99386280704202E-08"
        iyy="0.000363640124291398"
        iyz="5.87423692067242E-08"
        izz="1.34783779607938E-06" />
    </inertial>
    <visual>
      <origin
        xyz="0 0 0"
        rpy="0 0 0" />
      <geometry>
        <mesh
          filename="../meshes/l_r_tendon.STL" />
      </geometry>
      <material
        name="">
        <color
          rgba="0.890196078431372 0.890196078431372 0.913725490196078 1" />
      </material>
    </visual>
    <collision>
      <origin
        xyz="0 0 0"
        rpy="0 0 0" />
      <geometry>
        <mesh
          filename="../meshes/l_r_tendon.STL" />
      </geometry>
    </collision>
  </link> -->
  <!-- <drake:joint 
    name="l_r_tendon" 
    type="universal">
    <origin 
      xyz="-0.0560267810612719 0 0.014999993463731" 
      rpy="0 0 0" />
    <parent link="l_r_bar" />
    <child link="l_r_tendon" />
  </drake:joint> -->
  <!-- <frame link="l_r_tendon" name="l_r_tendon_frame" xyz="0 0 -0.29134" /> -->
  <!-- <joint
    name="l_r_tendon"
    type="fixed">
    <origin
      xyz="-0.0560267810612716 0 0.0149999934637309"
      rpy="0 0 0" />
    <parent
      link="l_r_bar" />
    <child
      link="l_r_tendon" />
    <axis
      xyz="0 1 0" />
  </joint> -->
  <link
    name="r_leg_roll">
    <inertial>
      <origin
        xyz="-0.00483930 -0.00000000 -0.00362787"
        rpy="0 0 0" />
      <mass
        value="1.854" />
      <inertia
        ixx="0.00362787"
        ixy="0.00000109"
        ixz="0.00001393"
        iyy="0.00316718"
        iyz="0.00000000"
        izz="0.00418540" />
    </inertial>
    <visual>
      <origin
        xyz="0 0 0"
        rpy="0 0 0" />
      <geometry>
        <mesh
          filename="../meshes/r_leg_roll.STL" />
      </geometry>
      <material
        name="">
        <color
          rgba="0.890196078431372 0.890196078431372 0.913725490196078 1" />
      </material>
    </visual>
    <!-- <collision>
      <origin
        xyz="0 0 0"
        rpy="0 0 0" />
      <geometry>
        <mesh
          filename="../meshes/r_leg_roll.STL" />
      </geometry>
    </collision> -->
  </link>
  <joint
    name="r_leg_roll"
    type="revolute">
    <origin
      xyz="-0.00250000000035087 -0.0870000000000446 -0.066000000004924"
      rpy="0 0 0" />
    <parent
      link="torso" />
    <child
      link="r_leg_roll" />
    <axis
      xyz="1 0 0" />
    <limit 
      lower="-0.64" upper="0.3" effort="200" velocity="14" />
  </joint>
  <!-- <transmission type="SimpleTransmission">
    <joint name="r_leg_roll" />
    <actuator name="r_leg_roll_motor" />
  </transmission> -->
  <link
    name="r_leg_yaw">
    <inertial>
      <origin
        xyz="-0.00000000 -0.00487081 -0.06699333"
        rpy="0 0 0" />
      <mass
        value="0.358" />
      <inertia
        ixx="0.00299812"
        ixy="-0.0"
        ixz="0.0"
        iyy="0.00217705"
        iyz="-0.0"
        izz="0.00112966" />
      <!-- <inertia
        ixx="0.00299812"
        ixy="-0.00000002"
        ixz="0.00000003"
        iyy="0.00217705"
        iyz="-0.00009995"
        izz="0.00112966" /> -->
    </inertial>
    <visual>
      <origin
        xyz="0 0 0"
        rpy="0 0 0" />
      <geometry>
        <mesh
          filename="../meshes/r_leg_yaw.STL" />
      </geometry>
      <material
        name="">
        <color
          rgba="0.890196078431372 0.890196078431372 0.913725490196078 1" />
      </material>
    </visual>
    <!-- <collision>
      <origin
        xyz="0 0 0"
        rpy="0 0 0" />
      <geometry>
        <mesh
          filename="../meshes/r_leg_yaw.STL" />
      </geometry>
    </collision> -->
  </link>
  <joint
    name="r_leg_yaw"
    type="revolute">
    <origin
      xyz="0 0 0"
      rpy="0 0 0" />
    <parent
      link="r_leg_roll" />
    <child
      link="r_leg_yaw" />
    <axis
      xyz="0 0 1" />
    <limit 
      lower="-0.51" upper="1.02" effort="100" velocity="14" />
  </joint>
  <!-- <transmission type="SimpleTransmission">
    <joint 
      name="r_leg_yaw" />
    <actuator name="r_leg_yaw_motor" />
  </transmission> -->
  <link
    name="r_leg_pitch">
    <inertial>
      <origin
        xyz="0.00593676 -0.00197199 -0.09495983"
        rpy="0 0 0" />
      <mass
        value="6.094" />
        <inertia
        ixx="0.13349179"
        ixy="-0.00031558"
        ixz="0.01086640"
        iyy="0.13643568"
        iyz="-0.00145346"
        izz="0.01382005" />
      <!-- <inertia
        ixx="0.13349179"
        ixy="0.00031558"
        ixz="-0.01086640"
        iyy="0.13643568"
        iyz="0.00145346"
        izz="0.01382005" /> -->
    </inertial>
    <visual>
      <origin
        xyz="0 0 0"
        rpy="0 0 0" />
      <geometry>
        <mesh
          filename="../meshes/r_leg_pitch.STL" />
      </geometry>
      <material
        name="">
        <color
          rgba="0.890196078431372 0.890196078431372 0.913725490196078 1" />
      </material>
    </visual>
    <!-- <collision>
      <origin
        xyz="0 0 0"
        rpy="0 0 0" />
      <geometry>
        <mesh
          filename="../meshes/r_leg_pitch.STL" />
      </geometry>
    </collision> -->
  </link>
  <joint
    name="r_leg_pitch"
    type="revolute">
    <origin
      xyz="0 0 -0.125000000000001"
      rpy="0 0 0" />
    <parent
      link="r_leg_yaw" />
    <child
      link="r_leg_pitch" />
    <axis
      xyz="0 1 0" />
    <limit 
      lower="-1.785" upper="1.02" effort="200" velocity="14" />
  </joint>
  <!-- <transmission type="SimpleTransmission">
    <joint name="r_leg_pitch" />
    <actuator name="r_leg_pitch_motor" />
  </transmission> -->
  <link
    name="r_knee">
    <inertial>
      <origin
        xyz="0.00131187 -0.00020666 -0.15764341"
        rpy="0 0 0" />
      <mass
        value="1.968" />
      <inertia
        ixx="0.07729702"
        ixy="0.00000207"
        ixz="-0.00005536"
        iyy="0.07755038"
        iyz="-0.00028214"
        izz="0.00121467" />
    </inertial>
    <visual>
      <origin
        xyz="0 0 0"
        rpy="0 0 0" />
      <geometry>
        <mesh
          filename="../meshes/r_knee.STL" />
      </geometry>
      <material
        name="">
        <color
          rgba="0.890196078431372 0.890196078431372 0.913725490196078 1" />
      </material>
    </visual>
    <!-- <collision>
      <origin
        xyz="0 0 0"
        rpy="0 0 0" />
      <geometry>
        <mesh
          filename="../meshes/r_knee.STL" />
      </geometry>
    </collision> -->
  </link>
  <joint
    name="r_knee"
    type="revolute">
    <origin
      xyz="0.0419999999999999 0 -0.371446748811989"
      rpy="0 0 0" />
    <parent
      link="r_leg_pitch" />
    <child
      link="r_knee" />
    <axis
      xyz="0 1 0" />
    <limit 
      lower="-0.1" upper="1.95" effort="200" velocity="14" />
  </joint>
  <!-- <transmission type="SimpleTransmission">
    <joint name="r_knee" />
    <actuator name="r_knee_motor" />
  </transmission> -->
  <link
    name="r_foot_pitch">
    <inertial>
      <origin
        xyz="-2.20869654975198E-07 2.20870146810936E-07 4.44089209850063E-16"
        rpy="0 0 0" />
      <mass
        value="0.071" />
      <inertia
        ixx="8.65317607419045E-10"
        ixy="-4.38657646635503E-19"
        ixz="-3.49395618891317E-14"
        iyy="8.65317607419045E-10"
        iyz="-3.447500777446E-14"
        izz="1.52218316128676E-09" />
    </inertial>
    <visual>
      <origin
        xyz="0 0 0"
        rpy="0 0 0" />
      <geometry>
        <mesh
          filename="../meshes/r_foot_pitch.STL" />
      </geometry>
      <material
        name="">
        <color
          rgba="0.890196078431372 0.890196078431372 0.913725490196078 1" />
      </material>
    </visual>
    <!-- <collision>
      <origin
        xyz="0 0 0"
        rpy="0 0 0" />
      <geometry>
        <mesh
          filename="../meshes/r_foot_pitch.STL" />
      </geometry>
    </collision> -->
  </link>
  <joint
    name="r_foot_pitch"
    type="revolute">
    <origin
      xyz="0 0 -0.445999999999999"
      rpy="0 0 0" />
    <parent
      link="r_knee" />
    <child
      link="r_foot_pitch" />
    <axis
      xyz="0 1 0" />
    <limit 
      lower="-0.7" upper="0.7" effort="70" velocity="10" />
  </joint>
  <link
    name="r_foot_roll">
    <inertial>
      <origin
        xyz="-0.00253560414136999 8.23854037115823E-06 -0.0377214649834521"
        rpy="0 0 0" />
      <mass
        value="0.302" />
      <inertia
        ixx="0.000124764742478312"
        ixy="-2.08372197394019E-08"
        ixz="5.85764784216475E-06"
        iyy="0.000552202126631586"
        iyz="-1.48804312214361E-08"
        izz="0.000647202029682914" />
    </inertial>
    <visual>
      <origin
        xyz="0 0 0"
        rpy="0 0 0" />
      <geometry>
        <mesh
          filename="../meshes/r_foot_roll.STL" />
      </geometry>
      <material
        name="">
        <color
          rgba="0.890196078431372 0.890196078431372 0.913725490196078 1" />
      </material>
    </visual>
    <collision>
      <origin
        xyz="0 0 0"
        rpy="0 0 0" />
      <geometry>
        <mesh
          filename="../meshes/r_foot_roll.STL" />
      </geometry>
    </collision>
    <visual>
      <origin rpy="0 0 0" xyz="-0.075 0.03 -0.055" />
      <geometry>
        <sphere radius="0.005" />
      </geometry>
    </visual>
    <collision>
      <origin rpy="0 0 0" xyz="-0.075 0.03 -0.055" />
      <geometry>
        <sphere radius="0.005" />
      </geometry>
    </collision>
    <visual>
      <origin rpy="0 0 0" xyz="-0.075 -0.03 -0.055" />
      <geometry>
        <sphere radius="0.005" />
      </geometry>
    </visual>
    <collision>
      <origin rpy="0 0 0" xyz="-0.075 -0.03 -0.055" />
      <geometry>
        <sphere radius="0.005" />
      </geometry>
    </collision>

    <visual>
      <origin rpy="0 0 0" xyz="0.075 0.03 -0.055" />
      <geometry>
        <sphere radius="0.005" />
      </geometry>
    </visual>
    <collision>
      <origin rpy="0 0 0" xyz="0.075 0.03 -0.055" />
      <geometry>
        <sphere radius="0.005" />
      </geometry>
    </collision>
    <visual>
      <origin rpy="0 0 0" xyz="0.075 -0.03 -0.055" />
      <geometry>
        <sphere radius="0.005" />
      </geometry>
    </visual>
    <collision>
      <origin rpy="0 0 0" xyz="0.075 -0.03 -0.055" />
      <geometry>
        <sphere radius="0.005" />
      </geometry>
    </collision>
  </link>
  <joint
    name="r_foot_roll"
    type="revolute">
    <origin
      xyz="0 0 0"
      rpy="0 0 0" />
    <parent
      link="r_foot_pitch" />
    <child
      link="r_foot_roll" />
    <axis
      xyz="1 0 0" />
    <limit 
      lower="-0.51" upper="0.51" effort="70" velocity="10" />
  </joint>
  <frame link="r_foot_roll" name="r_foot_roll_l_frame" xyz="-0.0563 0.025 0.01473" />
  <frame link="r_foot_roll" name="r_foot_roll_r_frame" xyz="-0.0563 -0.025 0.01473" />
  <!-- <link
    name="r_r_bar">
    <inertial>
      <origin
        xyz="-0.016687640424117 -0.00762419483038657 0.00446861619310002"
        rpy="0 0 0" />
      <mass
        value="0.024" />
      <inertia
        ixx="3.76382096519523E-06"
        ixy="1.60357441586418E-06"
        ixz="2.75428206064885E-06"
        iyy="1.63386822509857E-05"
        iyz="-4.2920394890412E-07"
        izz="1.33163697724618E-05" />
    </inertial>
    <visual>
      <origin
        xyz="0 0 0"
        rpy="0 0 0" />
      <geometry>
        <mesh
          filename="../meshes/r_r_bar.STL" />
      </geometry>
      <material
        name="">
        <color
          rgba="0.890196078431372 0.890196078431372 0.913725490196078 1" />
      </material>
    </visual>
    <collision>
      <origin
        xyz="0 0 0"
        rpy="0 0 0" />
      <geometry>
        <mesh
          filename="../meshes/r_r_bar.STL" />
      </geometry>
    </collision>
  </link> -->
  <!-- <joint
    name="r_r_bar"
    type="fixed">
    <origin
      xyz="0 -0.0250000000000014 -0.0900000000000001"
      rpy="0 0 0" />
    <parent
      link="r_knee" />
    <child
      link="r_r_bar" />
    <axis
      xyz="0 1 0" />
    <limit lower="-3.14" upper="3.14" effort="100" velocity="25" />
  </joint> -->
  <!-- <link
    name="r_r_tendon">
    <inertial>
      <origin
        xyz="-3.54867378138425E-05 6.32490609233649E-05 -0.150986741096076"
        rpy="0 0 0" />
      <mass
        value="0.088" />
      <inertia
        ixx="0.00020807827417541"
        ixy="1.36718291012234E-11"
        ixz="-4.87672526844241E-08"
        iyy="0.000207622360212094"
        iyz="4.82866594982301E-08"
        izz="1.17120018264705E-06" />
    </inertial>
    <visual>
      <origin
        xyz="0 0 0"
        rpy="0 0 0" />
      <geometry>
        <mesh
          filename="../meshes/r_r_tendon.STL" />
      </geometry>
      <material
        name="">
        <color
          rgba="0.890196078431372 0.890196078431372 0.913725490196078 1" />
      </material>
    </visual>
    <collision>
      <origin
        xyz="0 0 0"
        rpy="0 0 0" />
      <geometry>
        <mesh
          filename="../meshes/r_r_tendon.STL" />
      </geometry>
    </collision>
  </link> -->
  <!-- <drake:joint 
    name="r_r_tendon" 
    type="universal">
    <origin 
      xyz="-0.0560267814521323 0 0.0149999920038325" 
      rpy="0 0 0" />
    <parent 
      link="r_r_bar" />
    <child 
      link="r_r_tendon" />
  </drake:joint> -->
  <!-- <frame link="r_r_tendon" name="r_r_tendon_frame" xyz="0 0 -0.3563" /> -->
  <!-- <transmission type="SimpleTransmission">
    <joint name="r_r_bar" />
    <actuator name="r_r_bar_motor">
      <drake:gear_ratio value="10.0" />
      <drake:rotor_inertia value="0.0001002" />
    </actuator>
  </transmission> -->
  <!-- <joint
    name="r_r_tendon"
    type="fixed">
    <origin
      xyz="-0.0560272920021874 0 0.014998084907814"
      rpy="0 0 0" />
    <parent
      link="r_r_bar" />
    <child
      link="r_r_tendon" />
    <axis
      xyz="0 1 0" />
  </joint> -->
  <!-- <link
    name="r_l_bar">
    <inertial>
      <origin
        xyz="-0.016688087961719 0.0076241912885387 0.00446702228828433"
        rpy="0 0 0" />
      <mass
        value="0.024" />
      <inertia
        ixx="3.76441261728869E-06"
        ixy="-1.60351245171018E-06"
        ixz="2.75531232497998E-06"
        iyy="1.63386673714102E-05"
        iyz="4.29427169376852E-07"
        izz="1.33157624817472E-05" />
    </inertial>
    <visual>
      <origin
        xyz="0 0 0"
        rpy="0 0 0" />
      <geometry>
        <mesh
          filename="../meshes/r_l_bar.STL" />
      </geometry>
      <material
        name="">
        <color
          rgba="0.890196078431372 0.890196078431372 0.913725490196078 1" />
      </material>
    </visual>
    <collision>
      <origin
        xyz="0 0 0"
        rpy="0 0 0" />
      <geometry>
        <mesh
          filename="../meshes/r_l_bar.STL" />
      </geometry>
    </collision>
  </link> -->
  <!-- <joint
    name="r_l_bar"
    type="fixed">
    <origin
      xyz="0 0.025 -0.155"
      rpy="0 0 0" />
    <parent
      link="r_knee" />
    <child
      link="r_l_bar" />
    <axis
      xyz="0 1 0" />
  </joint> -->
  <!-- <transmission type="SimpleTransmission">
    <joint name="r_l_bar" />
    <actuator name="r_l_bar_motor">
      <drake:gear_ratio value="10.0" />
      <drake:rotor_inertia value="0.0001002" />
    </actuator>
  </transmission> -->
  <!-- <link
    name="r_l_tendon">
    <inertial>
      <origin
        xyz="-3.38743561054573E-05 -5.48291626958144E-05 -0.182365822114472"
        rpy="0 0 0" />
      <mass
        value="0.102" />
      <inertia
        ixx="0.000364218805685306"
        ixy="-1.04791584212972E-11"
        ixz="-6.99581914178355E-08"
        iyy="0.000363638708857047"
        iyz="-5.87413433425947E-08"
        izz="1.34783664470708E-06" />
    </inertial>
    <visual>
      <origin
        xyz="0 0 0"
        rpy="0 0 0" />
      <geometry>
        <mesh
          filename="../meshes/r_l_tendon.STL" />
      </geometry>
      <material
        name="">
        <color
          rgba="0.890196078431372 0.890196078431372 0.913725490196078 1" />
      </material>
    </visual>
    <collision>
      <origin
        xyz="0 0 0"
        rpy="0 0 0" />
      <geometry>
        <mesh
          filename="../meshes/r_l_tendon.STL" />
      </geometry>
    </collision>
  </link> -->
  <!-- <drake:joint 
    name="r_l_tendon" 
    type="universal">
    <origin 
      xyz="-0.0560267810612721 0 0.0149999934637293" 
      rpy="0 0 0" />
    <parent 
      link="r_l_bar" />
    <child 
      link="r_l_tendon" />
  </drake:joint> -->
  <!-- <frame link="r_l_tendon" name="r_l_tendon_frame" xyz="0 0 -0.2913" /> -->
  <!-- <joint
    name="r_l_tendon"
    type="fixed">
    <origin
      xyz="-0.0560274063891502 0 0.0149976575939389"
      rpy="0 0 0" />
    <parent
      link="r_l_bar" />
    <child
      link="r_l_tendon" />
    <axis
      xyz="0 1 0" />
    <limit lower="-3.14" upper="3.14" effort="100" velocity="25" />
  </joint> -->
  <!-- ================================================================================================ -->
  <!-- left arm -->
 <link
    name="l_arm_pitch">
    <inertial>
      <origin
        xyz="0.0146835191418715 -0.0166604103758634 -6.82857133371129E-05"
        rpy="0 0 0" />
      <mass
        value="0.165847319965906" />
      <inertia
        ixx="0.0002674432873971"
        ixy="-2.5654089149164E-05"
        ixz="-1.72966133127553E-07"
        iyy="0.000125796784291983"
        iyz="-1.66717296343013E-06"
        izz="0.000196186976742156" />
    </inertial>
    <visual>
      <origin
        xyz="0 0 0"
        rpy="0 0 0" />
      <geometry>
        <mesh
          filename="../meshes/l_arm_pitch.STL" />
      </geometry>
      <material
        name="">
        <color
          rgba="1 1 1 1" />
      </material>
    </visual>    
  </link>
  <joint
    name="l_arm_pitch"
    type="fixed">
    <origin
      xyz="-0.0175475823124921 0.254700000000031 0.324500000000024"
      rpy="0 0 0" />
    <parent
      link="torso" />
    <child
      link="l_arm_pitch" />
    <axis
      xyz="0 1 0" />
    <limit lower="-1.57" upper="1.57" effort="100" velocity="35" />
  </joint>
  <!-- <transmission type="SimpleTransmission">
    <joint name="l_arm_pitch" />
    <actuator name="l_arm_pitch_motor" />
  </transmission> -->
  <link
    name="l_arm_roll">
    <inertial>
      <origin
        xyz="0.0222872651779299 0.0156945544195473 -0.0202262244341484"
        rpy="0 0 0" />
      <mass
        value="0.141426581413056" />
      <inertia
        ixx="0.000160370067223081"
        ixy="6.30811840859269E-06"
        ixz="-1.13259246453495E-05"
        iyy="0.000262365778589962"
        iyz="3.14941259087024E-05"
        izz="0.00023601403628197" />
    </inertial>
    <visual>
      <origin
        xyz="0 0 0"
        rpy="0 0 0" />
      <geometry>
        <mesh
          filename="../meshes/l_arm_roll.STL" />
      </geometry>
      <material
        name="">
        <color
          rgba="1 1 1 1" />
      </material>
    </visual>
   
  </link>
  <joint
    name="l_arm_roll"
    type="fixed">
    <origin
      xyz="0 0 0"
      rpy="0 0 0" />
    <parent
      link="l_arm_pitch" />
    <child
      link="l_arm_roll" />
    <axis
      xyz="1 0 0" />
    <limit lower="0" upper="3.06" effort="100" velocity="20" />

  </joint>
  <!-- <transmission type="SimpleTransmission">
    <joint name="l_arm_roll" />
    <actuator name="l_arm_roll_motor" />
  </transmission> -->

  <link
    name="l_arm_yaw">
    <inertial>
      <origin
        xyz="6.16940440451783E-05 0.00525815062784063 -0.128821944854616"
        rpy="0 0 0" />
      <mass
        value="0.147794102819133" />
      <inertia
        ixx="7.00575957554699E-05"
        ixy="-6.81658291272877E-10"
        ixz="2.69427050743199E-10"
        iyy="8.53612265336777E-05"
        iyz="6.95899873075699E-06"
        izz="8.82223899453285E-05" />
    </inertial>
    <visual>
      <origin
        xyz="0 0 0"
        rpy="0 0 0" />
      <geometry>
        <mesh
          filename="../meshes/l_arm_yaw.STL" />
      </geometry>
      <material
        name="">
        <color
          rgba="1 1 1 1" />
      </material>
    </visual>
    
  </link>
  <joint
    name="l_arm_yaw"
    type="fixed">
    <origin
      xyz="0 0 0"
      rpy="0 0 0" />
    <parent
      link="l_arm_roll" />
    <child
      link="l_arm_yaw" />
    <axis
      xyz="0 0 1" />
    <limit lower="-1.57" upper="1.57" effort="100" velocity="20" />

  </joint>
  <!-- <transmission type="SimpleTransmission">
    <joint name="l_arm_yaw" />
    <actuator name="l_arm_yaw_motor" />
  </transmission> -->

  <link
    name="l_forearm_pitch">
    <inertial>
      <origin
        xyz="-1.4281929799409E-05 0.00938313949959718 -0.0522687552263489"
        rpy="0 0 0" />
      <mass
        value="0.170164726102009" />
      <inertia
        ixx="9.558084476069E-05"
        ixy="-4.53863490387433E-08"
        ixz="5.39342118513253E-08"
        iyy="0.000126326373178391"
        iyz="-9.58160032696958E-06"
        izz="0.000121032474884238" />
    </inertial>
    <visual>
      <origin
        xyz="0 0 0"
        rpy="0 0 0" />
      <geometry>
        <mesh
          filename="../meshes/l_forearm_pitch.STL" />
      </geometry>
      <material
        name="">
        <color
          rgba="1 1 1 1" />
      </material>
    </visual>
    
  </link>
  <joint
    name="l_forearm_pitch"
    type="fixed">
    <origin
      xyz="0 0 -0.163599999999998"
      rpy="0 0 0" />
    <parent
      link="l_arm_yaw" />
    <child
      link="l_forearm_pitch" />
    <axis
      xyz="0 1 0" />
    <limit lower="-1.57" upper="0" effort="100" velocity="20" />

  </joint>
  <!-- <transmission type="SimpleTransmission">
    <joint name="l_forearm_pitch" />
    <actuator name="l_forearm_pitch_motor" />
  </transmission> -->
  <link
    name="l_hand_yaw">
    <inertial>
      <origin
        xyz="0.000113133463122583 0.00969227839919062 0.0817960696431681"
        rpy="0 0 0" />
      <mass
        value="0.157336288737043" />
      <inertia
        ixx="7.64923984145487E-05"
        ixy="8.51098127601464E-09"
        ixz="-1.4070355859132E-08"
        iyy="0.000122231132554914"
        iyz="1.11226968994633E-06"
        izz="8.44935061342021E-05" />
    </inertial>
    <visual>
      <origin
        xyz="0 0 0"
        rpy="0 0 0" />
      <geometry>
        <mesh
          filename="../meshes/l_hand_yaw.STL" />
      </geometry>
      <material
        name="">
        <color
          rgba="1 1 1 1" />
      </material>
    </visual>   
  </link>
  <joint
    name="l_hand_yaw"
    type="fixed">
    <origin
      xyz="0 0 -0.191049997298861"
      rpy="0 0 0" />
    <parent
      link="l_forearm_pitch" />
    <child
      link="l_hand_yaw" />
    <axis
      xyz="0 0 1" />
    <limit lower="-1.57" upper="1.57" effort="100" velocity="20" />
  </joint>
  <!-- <transmission type="SimpleTransmission">
    <joint name="l_hand_yaw" />
    <actuator name="l_hand_yaw_motor" />
  </transmission> -->
  <link
    name="l_hand_pitch">
    <inertial>
      <origin
        xyz="0.00810609786663821 0.00489663150092601 0.00622488608908427"
        rpy="0 0 0" />
      <mass
        value="0.0853891779246004" />
      <inertia
        ixx="4.77321490368476E-05"
        ixy="3.05261917457107E-06"
        ixz="4.77827164947654E-06"
        iyy="3.43814769749139E-05"
        iyz="-4.59311499587155E-06"
        izz="2.49955336560135E-05" />
    </inertial>
    <visual>
      <origin
        xyz="0 0 0"
        rpy="0 0 0" />
      <geometry>
        <mesh
          filename="../meshes/l_hand_pitch.STL" />
      </geometry>
      <material
        name="">
        <color
          rgba="1 1 1 1" />
      </material>
    </visual>    
  </link>
  <joint
    name="l_hand_pitch"
    type="fixed">
    <origin
      xyz="0 0 0"
      rpy="0 0 0" />
    <parent
      link="l_hand_yaw" />
    <child
      link="l_hand_pitch" />
    <axis
      xyz="0 1 0" />
    <limit lower="-0.51" upper="0.51" effort="100" velocity="15" />

  </joint>
  <!-- <transmission type="SimpleTransmission">
    <joint name="l_hand_pitch" />
    <actuator name="l_hand_pitch_motor" />
  </transmission> -->
  <link
    name="l_hand_roll">
    <inertial>
      <origin
        xyz="0.0055750097939089 0.00647363667890594 -0.0826245715087526"
        rpy="0 0 0" />
      <mass
        value="0.505839717252105" />
      <inertia
        ixx="8.04371746531483E-05"
        ixy="2.770174858381E-07"
        ixz="-4.63354764745673E-06"
        iyy="0.000116536814280971"
        iyz="1.04534418501281E-05"
        izz="0.000111690600253046" />
    </inertial>
    <visual>
      <origin
        xyz="0 0 0"
        rpy="0 0 0" />
      <geometry>
        <mesh
          filename="../meshes/l_hand_roll.STL" />
      </geometry>
      <material
        name="">
        <color
          rgba="1 1 1 1" />
      </material>
    </visual>   
  </link>
  <joint
    name="l_hand_roll"
    type="fixed">
    <origin
      xyz="0 0 0"
      rpy="0 0 0" />
    <parent
      link="l_hand_pitch" />
    <child
      link="l_hand_roll" />
    <axis
      xyz="1 0 0" />
    <limit lower="-1.57" upper="1.57" effort="100" velocity="15" />
  </joint>
  <!-- <transmission type="SimpleTransmission">
    <joint name="l_hand_roll" />
    <actuator name="l_hand_roll_motor" />
  </transmission> -->
  <link
    name="r_arm_pitch">
    <inertial>
      <origin
        xyz="0.0146743511434554 0.0168298008224051 -8.16711977456031E-05"
        rpy="0 0 0" />
      <mass
        value="0.165729466195453" />
      <inertia
        ixx="0.000267364314112701"
        ixy="2.58822573731612E-05"
        ixz="-1.74450019197634E-07"
        iyy="0.000125724274127356"
        iyz="1.71810516637517E-06"
        izz="0.000196179895851995" />
    </inertial>
    <visual>
      <origin
        xyz="0 0 0"
        rpy="0 0 0" />
      <geometry>
        <mesh
          filename="../meshes/r_arm_pitch.STL" />
      </geometry>
      <material
        name="">
        <color
          rgba="1 1 1 1" />
      </material>
    </visual>   
  <!-- right arm -->
  </link>
  <joint
    name="r_arm_pitch"
    type="fixed">
    <origin
      xyz="-0.0175475823119764 -0.254700000000003 0.324500000000024"
      rpy="0 0 0" />
    <parent
      link="torso" />
    <child
      link="r_arm_pitch" />
    <axis
      xyz="0 1 0" />
    <limit lower="-1.57" upper="1.57" effort="100" velocity="35" />
  </joint>
  <!-- <transmission type="SimpleTransmission">
    <joint name="r_arm_pitch" />
    <actuator name="r_arm_pitch_motor" />
  </transmission> -->
  <link
    name="r_arm_roll">
    <inertial>
      <origin
        xyz="0.0223009070030529 -0.0156950170482436 -0.0202307747650334"
        rpy="0 0 0" />
      <mass
        value="0.141493827304592" />
      <inertia
        ixx="0.00016058853411588"
        ixy="-6.25733649402466E-06"
        ixz="-1.13236198708706E-05"
        iyy="0.000262566981542989"
        iyz="-3.14930415013909E-05"
        izz="0.000236151535262186" />
    </inertial>
    <visual>
      <origin
        xyz="0 0 0"
        rpy="0 0 0" />
      <geometry>
        <mesh
          filename="../meshes/r_arm_roll.STL" />
      </geometry>
      <material
        name="">
        <color
          rgba="1 1 1 1" />
      </material>
    </visual>   
  </link>
  <joint
    name="r_arm_roll"
    type="fixed">
    <origin
      xyz="0 0 0"
      rpy="0 0 0" />
    <parent
      link="r_arm_pitch" />
    <child
      link="r_arm_roll" />
    <axis
      xyz="1 0 0" />
    <limit lower="-3.06" upper="0" effort="100" velocity="20" />
  </joint>
  <!-- <transmission type="SimpleTransmission">
    <joint name="r_arm_roll" />
    <actuator name="r_arm_roll_motor" />
  </transmission> -->
  <link
    name="r_arm_yaw">
    <inertial>
      <origin
        xyz="-4.82749435400213E-05 -0.0052581506278393 -0.128821944854617"
        rpy="0 0 0" />
      <mass
        value="0.147794102819133" />
      <inertia
        ixx="7.00575957554697E-05"
        ixy="-6.81658260938682E-10"
        ixz="-2.69427064597612E-10"
        iyy="8.53612265336775E-05"
        iyz="-6.95899873075696E-06"
        izz="8.82223899453284E-05" />
    </inertial>
    <visual>
      <origin
        xyz="0 0 0"
        rpy="0 0 0" />
      <geometry>
        <mesh
          filename="../meshes/r_arm_yaw.STL" />
      </geometry>
      <material
        name="">
        <color
          rgba="1 1 1 1" />
      </material>
    </visual>    
  </link>
  <joint
    name="r_arm_yaw"
    type="fixed">
    <origin
      xyz="0 0 0"
      rpy="0 0 0" />
    <parent
      link="r_arm_roll" />
    <child
      link="r_arm_yaw" />
    <axis
      xyz="0 0 1" />
    <limit lower="-1.57" upper="1.57" effort="100" velocity="20" />
  </joint>
  <!-- <transmission type="SimpleTransmission">
    <joint name="r_arm_yaw" />
    <actuator name="r_arm_yaw_motor" />
  </transmission> -->
  <link
    name="r_forearm_pitch">
    <inertial>
      <origin
        xyz="-0.000127232990745116 -0.00951602649232586 -0.0522687552263488"
        rpy="0 0 0" />
      <mass
        value="0.170164726102011" />
      <inertia
        ixx="9.55808447606916E-05"
        ixy="-4.53863489774233E-08"
        ixz="-5.41060583443891E-08"
        iyy="0.000126326373178394"
        iyz="9.40982665987077E-06"
        izz="0.00012103247488424" />
    </inertial>
    <visual>
      <origin
        xyz="0 0 0"
        rpy="0 0 0" />
      <geometry>
        <mesh
          filename="../meshes/r_forearm_pitch.STL" />
      </geometry>
      <material
        name="">
        <color
          rgba="1 1 1 1" />
      </material>
    </visual>   
  </link>
  <joint
    name="r_forearm_pitch"
    type="fixed">
    <origin
      xyz="0 0 -0.1636"
      rpy="0 0 0" />
    <parent
      link="r_arm_yaw" />
    <child
      link="r_forearm_pitch" />
    <axis
      xyz="0 1 0" />
    <limit lower="-1.57" upper="0" effort="100" velocity="20" />
  </joint>
  <!-- <transmission type="SimpleTransmission">
    <joint name="r_forearm_pitch" />
    <actuator name="r_forearm_pitch_motor" />
  </transmission> -->
  <link
    name="r_hand_yaw">
    <inertial>
      <origin
        xyz="-0.000113133331993445 -0.0097448351680483 0.0817960724173413"
        rpy="0 0 0" />
      <mass
        value="0.157336288734482" />
      <inertia
        ixx="7.64923982725728E-05"
        ixy="8.51115986496426E-09"
        ixz="1.40703608309957E-08"
        iyy="0.000122231132626729"
        iyz="-1.11226978982942E-06"
        izz="8.44935061081861E-05" />
    </inertial>
    <visual>
      <origin
        xyz="0 0 0"
        rpy="0 0 0" />
      <geometry>
        <mesh
          filename="../meshes/r_hand_yaw.STL" />
      </geometry>
      <material
        name="">
        <color
          rgba="1 1 1 1" />
      </material>
    </visual>
  </link>
  <joint
    name="r_hand_yaw"
    type="fixed">
    <origin
      xyz="0 0 -0.191050000125729"
      rpy="0 0 0" />
    <parent
      link="r_forearm_pitch" />
    <child
      link="r_hand_yaw" />
    <axis
      xyz="0 0 1" />
    <limit lower="-1.57" upper="1.57" effort="100" velocity="20" />
  </joint>
  <!-- <transmission type="SimpleTransmission">
    <joint name="r_hand_yaw" />
    <actuator name="r_hand_yaw_motor" />
  </transmission> -->
  <link
    name="r_hand_pitch">
    <inertial>
      <origin
        xyz="0.00735986990228184 -0.0047523802551166 0.00605888061339196"
        rpy="0 0 0" />
      <mass
        value="0.0853891534309893" />
      <inertia
        ixx="4.77321358097824E-05"
        ixy="-2.99709432812988E-06"
        ixz="4.71488437974188E-06"
        iyy="3.42470226388499E-05"
        iyz="4.61094199971347E-06"
        izz="2.51299600072388E-05" />
    </inertial>
    <visual>
      <origin
        xyz="0 0 0"
        rpy="0 0 0" />
      <geometry>
        <mesh
          filename="../meshes/r_hand_pitch.STL" />
      </geometry>
      <material
        name="">
        <color
          rgba="1 1 1 1" />
      </material>
    </visual>
  </link>
  <joint
    name="r_hand_pitch"
    type="fixed">
    <origin
      xyz="0 0 0"
      rpy="0 0 0" />
    <parent
      link="r_hand_yaw" />
    <child
      link="r_hand_pitch" />
    <axis
      xyz="0 1 0" />
    <limit lower="-0.51" upper="0.51" effort="100" velocity="15" />
  </joint>
  <!-- <transmission type="SimpleTransmission">
    <joint name="r_hand_pitch" />
    <actuator name="r_hand_pitch_motor" />
  </transmission> -->
  <link
    name="r_hand_roll">
    <inertial>
      <origin
        xyz="0.0045944493552252 -0.00586927010446042 -0.0836324643988434"
        rpy="0 0 0" />
      <mass
        value="0.505839717252105" />
      <inertia
        ixx="0.000160651543151659"
        ixy="-5.37963063503334E-07"
        ixz="-9.47669219939636E-06"
        iyy="0.000229393712149694"
        iyz="-2.08351527945055E-05"
        izz="0.000219277776699058" />
    </inertial>
    <visual>
      <origin
        xyz="0 0 0"
        rpy="0 0 0" />
      <geometry>
        <mesh
          filename="../meshes/r_hand_roll.STL" />
      </geometry>
      <material
        name="">
        <color
          rgba="1 1 1 1" />
      </material>
    </visual>
  </link>
  <joint
    name="r_hand_roll"
    type="fixed">
    <origin
      xyz="0 0 0"
      rpy="0 0 0" />
    <parent
      link="r_hand_pitch" />
    <child
      link="r_hand_roll" />
    <axis
      xyz="1 0 0" />
    <limit lower="-1.57" upper="1.57" effort="100" velocity="15" />
  </joint>
  <!-- <transmission type="SimpleTransmission">
    <joint name="r_hand_roll" />
    <actuator name="r_hand_roll_motor" />
  </transmission> -->
</robot>
