<?xml version="1.0" encoding="utf-8"?>
<!-- This URDF was automatically created by SolidWorks to URDF Exporter! Originally created by Stephen Brawner (brawner@gmail.com) 
     Commit Version: 1.6.0-4-g7f85cfe  Build Version: 1.6.7995.38578
     For more information, please see http://wiki.ros.org/sw_urdf_exporter -->
<robot
  name="biped_s5">
  <link
    name="r_knee">
    <inertial>
      <origin
        xyz="0.00114478713288289 0.00015085717879465 -0.172234696219894"
        rpy="0 0 0" />
      <mass
        value="1.968" />
      <inertia
        ixx="0.00536823957167446"
        ixy="-2.23779727410624E-07"
        ixz="-8.68433497243911E-05"
        iyy="0.00554716033276625"
        iyz="-7.33881773534714E-06"
        izz="0.00023550351182021" />
    </inertial>
    <visual>
      <origin
        xyz="0 0 0"
        rpy="0 0 0" />
      <geometry>
        <mesh
          filename="../meshes/r_knee.obj" />
      </geometry>
      <material
        name="">
        <color
          rgba="0.792156862745098 0.819607843137255 0.933333333333333 1" />
      </material>
    </visual>
    <!-- <collision>
      <origin
        xyz="0 0 0"
        rpy="0 0 0" />
      <geometry>
        <mesh
          filename="../meshes/r_knee.obj" />
      </geometry>
    </collision> -->
  </link>
  <link
    name="r_foot_pitch">
    <inertial>
      <origin
        xyz="-2.20869654975198E-07 2.20870146810936E-07 4.44089209850063E-16"
        rpy="0 0 0" />
      <mass
        value="0.071" />
      <inertia
        ixx="8.65317607419045E-10"
        ixy="-4.38657646635503E-19"
        ixz="-3.49395618891317E-14"
        iyy="8.65317607419045E-10"
        iyz="-3.447500777446E-14"
        izz="1.52218316128676E-09" />
    </inertial>
    <visual>
      <origin
        xyz="0 0 0"
        rpy="0 0 0" />
      <geometry>
        <mesh
          filename="../meshes/r_foot_pitch.obj" />
      </geometry>
      <material
        name="">
        <color
          rgba="1 1 1 1" />
      </material>
    </visual>
    <!-- <collision>
      <origin
        xyz="0 0 0"
        rpy="0 0 0" />
      <geometry>
        <mesh
          filename="../meshes/r_foot_pitch.obj" />
      </geometry>
    </collision> -->
  </link>
  <joint
    name="r_foot_pitch"
    type="revolute">
    <origin
      xyz="0 0 -0.445999999999999"
      rpy="0 0 0" />
    <parent
      link="r_knee" />
    <child
      link="r_foot_pitch" />
    <axis
      xyz="0 1 0" />
    <limit
      lower="-1.50"
      upper="1.50"
      effort="74"
      velocity="47" />
  </joint>
  <link
    name="r_foot_roll">
    <inertial>
      <origin
        xyz="-0.00253560414136999 8.23854037115823E-06 -0.0377214649834521"
        rpy="0 0 0" />
      <mass
        value="0.302" />
      <inertia
        ixx="0.000124764742478312"
        ixy="-2.08372197394019E-08"
        ixz="5.85764784216475E-06"
        iyy="0.000552202126631586"
        iyz="-1.48804312214361E-08"
        izz="0.000647202029682914" />
    </inertial>
    <visual>
      <origin
        xyz="0 0 0"
        rpy="0 0 0" />
      <geometry>
        <mesh
          filename="../meshes/r_foot_roll.obj" />
      </geometry>
      <material
        name="">
        <color
          rgba="0.792156862745098 0.819607843137255 0.933333333333333 1" />
      </material>
    </visual>
    <!-- <collision>
      <origin
        xyz="0 0 0"
        rpy="0 0 0" />
      <geometry>
        <mesh
          filename="../meshes/r_foot_roll.obj" />
      </geometry>
    </collision> -->
  </link>
  <joint
    name="r_foot_roll"
    type="continuous">
    <origin
      xyz="0 0 0"
      rpy="0 0 0" />
    <parent
      link="r_foot_pitch" />
    <child
      link="r_foot_roll" />
    <axis
      xyz="1 0 0" />
    <limit
      lower="-3.14"
      upper="3.14"
    />
  </joint>
  
  <link
    name="r_r_bar">
    <inertial>
      <origin
        xyz="-0.016687640424117 -0.00762419483038657 0.00446861619310002"
        rpy="0 0 0" />
      <mass
        value="0.024" />
      <inertia
        ixx="3.76382096519523E-06"
        ixy="1.60357441586418E-06"
        ixz="2.75428206064885E-06"
        iyy="1.63386822509857E-05"
        iyz="-4.2920394890412E-07"
        izz="1.33163697724618E-05" />
    </inertial>
    <visual>
      <origin
        xyz="0 0 0"
        rpy="0 0 0" />
      <geometry>
        <mesh
          filename="../meshes/r_r_bar.obj" />
      </geometry>
      <material
        name="">
        <color
          rgba="0.890196078431372 0.890196078431372 0.913725490196078 1" />
      </material>
    </visual>
    <!-- <collision>
      <origin
        xyz="0 0 0"
        rpy="0 0 0" />
      <geometry>
        <mesh
          filename="../meshes/r_r_bar.obj" />
      </geometry>
    </collision> -->
  </link>
  <!-- <frame link="r_r_bar" name="r_r_bar_frame" xyz="0 0 0" /> -->
  <joint
    name="r_r_bar"
    type="revolute">
    <origin
      xyz="0 -0.0249999999999953 -0.0900000000000168"
      rpy="0 0 0" />
    <parent
      link="r_knee" />
    <child
      link="r_r_bar" />
    <axis
      xyz="0 1 0" />
    <limit
      lower="-3.14"
      upper="3.14" />
    <!-- <dynamics damping="0.1" friction="0."/> -->
  </joint>
  <transmission type="SimpleTransmission">
    <joint name="r_r_bar" />
    <actuator name="r_r_bar_motor">
      <drake:gear_ratio value="9.0" />
      <drake:rotor_inertia value="0.0001002" />
    </actuator>
  </transmission>
  <link
    name="r_r_tendon">
    <inertial>
      <origin
        xyz="-3.54867378138425E-05 6.32490609233649E-05 -0.150986741096076"
        rpy="0 0 0" />
      <mass
        value="0.088" />
      <inertia
        ixx="0.00020807827417541"
        ixy="1.36718291012234E-11"
        ixz="-4.87672526844241E-08"
        iyy="0.000207622360212094"
        iyz="4.82866594982301E-08"
        izz="1.17120018264705E-06" />
    </inertial>
    <visual>
      <origin
        xyz="0 0 0"
        rpy="0 0 0" />
      <geometry>
        <mesh
          filename="../meshes/r_r_tendon.obj" />
      </geometry>
      <material
        name="">
        <color
          rgba="0.792156862745098 0.819607843137255 0.933333333333333 1" />
      </material>
    </visual>
    <!-- <collision>
      <origin
        xyz="0 0 0"
        rpy="0 0 0" />
      <geometry>
        <mesh
          filename="../meshes/r_r_tendon.obj" />
      </geometry>
    </collision> -->
  </link>
  <drake:joint name="r_r_tendon" type="universal">
    <origin xyz="-0.0560267814521323 0 0.0149999920038325" rpy="0 0 0" />
    <parent link="r_r_bar" />
    <child link="r_r_tendon" />
  </drake:joint>
  <!-- <joint
    name="r_r_tendon"
    type="continuous">
    <origin
      xyz="-0.0560267814521323 0 0.0149999920038325"
      rpy="0 0 0" />
    <parent
      link="r_r_bar" />
    <child
      link="r_r_tendon" />
    <axis
      xyz="0 1 0" />
    <limit lower="-3.14" upper="3.14" effort="100" velocity="25" />
  </joint> -->
  <link
    name="r_l_bar">
    <inertial>
      <origin
        xyz="-0.016688087961719 0.0076241912885387 0.00446702228828433"
        rpy="0 0 0" />
      <mass
        value="0.024" />
      <inertia
        ixx="3.76441261728869E-06"
        ixy="-1.60351245171018E-06"
        ixz="2.75531232497998E-06"
        iyy="1.63386673714102E-05"
        iyz="4.29427169376852E-07"
        izz="1.33157624817472E-05" />
    </inertial>
    <visual>
      <origin
        xyz="0 0 0"
        rpy="0 0 0" />
      <geometry>
        <mesh
          filename="../meshes/r_l_bar.obj" />
      </geometry>
      <material
        name="">
        <color
          rgba="0.890196078431372 0.890196078431372 0.913725490196078 1" />
      </material>
    </visual>
    <!-- <collision>
      <origin
        xyz="0 0 0"
        rpy="0 0 0" />
      <geometry>
        <mesh
          filename="../meshes/r_l_bar.obj" />
      </geometry>
    </collision> -->
  </link>
  <!-- <frame link="r_l_bar" name="r_l_bar_frame" xyz="0 0 0" /> -->
  <joint
    name="r_l_bar"
    type="revolute">
    <origin
      xyz="0 0.0250000000000045 -0.155000000000003"
      rpy="0 0 0" />
    <parent
      link="r_knee" />
    <child
      link="r_l_bar" />
    <axis
      xyz="0 1 0" />
    <limit
      lower="-3.14"
      upper="3.14" />
  </joint>
  <transmission type="SimpleTransmission">
    <joint name="r_l_bar" />
    <actuator name="r_l_bar_motor">
      <drake:gear_ratio value="9.0" />
      <drake:rotor_inertia value="0.0001002" />
    </actuator>
  </transmission>
  <link
    name="r_l_tendon">
    <inertial>
      <origin
        xyz="-3.38743561054573E-05 -5.48291626958144E-05 -0.182365822114472"
        rpy="0 0 0" />
      <mass
        value="0.102" />
      <inertia
        ixx="0.000364218805685306"
        ixy="-1.04791584212972E-11"
        ixz="-6.99581914178355E-08"
        iyy="0.000363638708857047"
        iyz="-5.87413433425947E-08"
        izz="1.34783664470708E-06" />
    </inertial>
    <visual>
      <origin
        xyz="0 0 0"
        rpy="0 0 0" />
      <geometry>
        <mesh
          filename="../meshes/r_l_tendon.obj" />
      </geometry>
      <material
        name="">
        <color
          rgba="0.792156862745098 0.819607843137255 0.933333333333333 1" />
      </material>
    </visual>
  </link>
  <drake:joint name="r_l_tendon" type="universal">
    <origin xyz="-0.0560267810612721 0 0.0149999934637293" rpy="0 0 0" />
    <parent link="r_l_bar" />
    <child link="r_l_tendon" />
  </drake:joint>
  <!-- <joint
    name="r_l_tendon"
    type="continuous">
    <origin
      xyz="-0.0560267810612721 0 0.0149999934637293"
      rpy="0 0 0" />
    <parent
      link="r_l_bar" />
    <child
      link="r_l_tendon" />
    <axis
      xyz="0 1 0" />
    <limit lower="-3.14" upper="3.14" effort="100" velocity="25" />
  </joint> -->
  <frame link="r_r_tendon" name="r_r_tendon_frame" xyz="0 0 -0.3563" />
  <frame link="r_foot_roll" name="r_foot_roll_r_frame" xyz="-0.0563 -0.025 0.01473" />
  <drake:linear_bushing_rpy>
    <drake:bushing_frameA name="r_r_tendon_frame" />
    <drake:bushing_frameC name="r_foot_roll_r_frame" />
    <drake:bushing_force_stiffness value="0 0 0" />
    <drake:bushing_force_damping value="0 0 0" />
    <drake:bushing_torque_stiffness value="0 0 0" />
    <drake:bushing_torque_damping value="0 0 0" />
  </drake:linear_bushing_rpy>
  <frame link="r_l_tendon" name="r_l_tendon_frame" xyz="0 0 -0.2913" />
  <frame link="r_foot_roll" name="r_foot_roll_l_frame" xyz="-0.0563 0.025 0.01473" />
  <drake:linear_bushing_rpy>
    <drake:bushing_frameA name="r_l_tendon_frame" />
    <drake:bushing_frameC name="r_foot_roll_l_frame" />
    <drake:bushing_force_stiffness value="0 0 0" />
    <drake:bushing_force_damping value="0 0 0" />
    <drake:bushing_torque_stiffness value="0 0 0" />
    <drake:bushing_torque_damping value="0 0 0" />
  </drake:linear_bushing_rpy>
</robot>